<?xml version="1.0" ?>
<!-- =================================================================================== -->
<!-- |    This document was autogenerated by xacro from panda_arm_hand.urdf.xacro      | -->
<!-- |    EDITING THIS FILE BY HAND IS NOT RECOMMENDED                                 | -->
<!-- =================================================================================== -->
<robot name="panda" xmlns:xacro="http://www.ros.org/wiki/xacro">
    <link name="World" />
    <link name="panda_link0">
        <inertial>
            <origin xyz="0 0 0" rpy="0 0 0" />
            <mass value="3.06" />
            <inertia ixx="0.3" ixy="0.0" ixz="0.0" iyy="0.3" iyz="0.0" izz="0.3" />
        </inertial>
        <visual>
            <geometry>
                <mesh filename="package://franka_description/meshes/visual/link0.dae" />
            </geometry>
            <material name="panda_white" />
        </visual>
        <collision>
            <geometry>
                <mesh filename="package://franka_description/meshes/collision/link0.stl" />
            </geometry>
            <material name="panda_white" />
        </collision>
    </link>
    <joint name="virtual_joint" type="fixed">
        <parent link="World" />
        <child link="panda_link0" />
    </joint>
    <link name="panda_link1">
        <inertial>
            <origin xyz="0 0 0" rpy="0 0 0" />
            <mass value="3.06" />
            <inertia ixx="0.3" ixy="0.0" ixz="0.0" iyy="0.3" iyz="0.0" izz="0.3" />
        </inertial>
        <visual>
            <geometry>
                <mesh filename="package://franka_description/meshes/visual/link1.dae" />
            </geometry>
            <material name="panda_white" />
        </visual>
        <collision>
            <geometry>
                <mesh filename="package://franka_description/meshes/collision/link1.stl" />
            </geometry>
            <material name="panda_white" />
        </collision>
    </link>
    <joint name="panda_joint1" type="revolute">
        <safety_controller k_position="100.0" k_velocity="40.0" soft_lower_limit="-2.8973" soft_upper_limit="2.8973" />
        <origin rpy="0 0 0" xyz="0 0 0.333" />
        <parent link="panda_link0" />
        <child link="panda_link1" />
        <axis xyz="0 0 1" />
        <limit effort="87" lower="-2.9671" upper="2.9671" velocity="2.1750" />
    </joint>
    <link name="panda_link2">
        <inertial>
            <origin xyz="0 0 0" rpy="0 0 0" />
            <mass value="3.06" />
            <inertia ixx="0.3" ixy="0.0" ixz="0.0" iyy="0.3" iyz="0.0" izz="0.3" />
        </inertial>
        <visual>
            <geometry>
                <mesh filename="package://franka_description/meshes/visual/link2.dae" />
            </geometry>
            <material name="panda_white" />
        </visual>
        <collision>
            <geometry>
                <mesh filename="package://franka_description/meshes/collision/link2.stl" />
            </geometry>
            <material name="panda_white" />
        </collision>
    </link>
    <joint name="panda_joint2" type="revolute">
        <safety_controller k_position="100.0" k_velocity="40.0" soft_lower_limit="-1.7628" soft_upper_limit="1.7628" />
        <origin rpy="-1.57079632679 0 0" xyz="0 0 0" />
        <parent link="panda_link1" />
        <child link="panda_link2" />
        <axis xyz="0 0 1" />
        <limit effort="87" lower="-1.8326" upper="1.8326" velocity="2.1750" />
    </joint>
    <link name="panda_link3">
        <inertial>
            <origin xyz="0 0 0" rpy="0 0 0" />
            <mass value="3.06" />
            <inertia ixx="0.3" ixy="0.0" ixz="0.0" iyy="0.3" iyz="0.0" izz="0.3" />
        </inertial>
        <visual>
            <geometry>
                <mesh filename="package://franka_description/meshes/visual/link3.dae" />
            </geometry>
            <material name="panda_white" />
        </visual>
        <collision>
            <geometry>
                <mesh filename="package://franka_description/meshes/collision/link3.stl" />
            </geometry>
            <material name="panda_white" />
        </collision>
    </link>
    <joint name="panda_joint3" type="revolute">
        <safety_controller k_position="100.0" k_velocity="40.0" soft_lower_limit="-2.8973" soft_upper_limit="2.8973" />
        <origin rpy="1.57079632679 0 0" xyz="0 -0.316 0" />
        <parent link="panda_link2" />
        <child link="panda_link3" />
        <axis xyz="0 0 1" />
        <limit effort="87" lower="-2.9671" upper="2.9671" velocity="2.1750" />
    </joint>
    <link name="panda_link4">
        <inertial>
            <origin xyz="0 0 0" rpy="0 0 0" />
            <mass value="3.06" />
            <inertia ixx="0.3" ixy="0.0" ixz="0.0" iyy="0.3" iyz="0.0" izz="0.3" />
        </inertial>
        <visual>
            <geometry>
                <mesh filename="package://franka_description/meshes/visual/link4.dae" />
            </geometry>
            <material name="panda_white" />
        </visual>
        <collision>
            <geometry>
                <mesh filename="package://franka_description/meshes/collision/link4.stl" />
            </geometry>
            <material name="panda_white" />
        </collision>
    </link>
    <joint name="panda_joint4" type="revolute">
        <safety_controller k_position="100.0" k_velocity="40.0" soft_lower_limit="-3.0718" soft_upper_limit="-0.0698" />
        <origin rpy="1.57079632679 0 0" xyz="0.0825 0 0" />
        <parent link="panda_link3" />
        <child link="panda_link4" />
        <axis xyz="0 0 1" />
        <limit effort="87" lower="-3.1416" upper="0.0" velocity="2.1750" />
    </joint>
    <link name="panda_link5">
        <inertial>
            <origin xyz="0 0 0" rpy="0 0 0" />
            <mass value="3.06" />
            <inertia ixx="0.3" ixy="0.0" ixz="0.0" iyy="0.3" iyz="0.0" izz="0.3" />
        </inertial>
        <visual>
            <geometry>
                <mesh filename="package://franka_description/meshes/visual/link5.dae" />
            </geometry>
            <material name="panda_white" />
        </visual>
        <collision>
            <geometry>
                <mesh filename="package://franka_description/meshes/collision/link5.stl" />
            </geometry>
            <material name="panda_white" />
        </collision>
    </link>
    <joint name="panda_joint5" type="revolute">
        <safety_controller k_position="100.0" k_velocity="40.0" soft_lower_limit="-2.8973" soft_upper_limit="2.8973" />
        <origin rpy="-1.57079632679 0 0" xyz="-0.0825 0.384 0" />
        <parent link="panda_link4" />
        <child link="panda_link5" />
        <axis xyz="0 0 1" />
        <limit effort="12" lower="-2.9671" upper="2.9671" velocity="2.6100" />
    </joint>
    <link name="panda_link6">
        <inertial>
            <origin xyz="0 0 0" rpy="0 0 0" />
            <mass value="3.06" />
            <inertia ixx="0.3" ixy="0.0" ixz="0.0" iyy="0.3" iyz="0.0" izz="0.3" />
        </inertial>
        <visual>
            <geometry>
                <mesh filename="package://franka_description/meshes/visual/link6.dae" />
            </geometry>
            <material name="panda_white" />
        </visual>
        <collision>
            <geometry>
                <mesh filename="package://franka_description/meshes/collision/link6.stl" />
            </geometry>
            <material name="panda_white" />
        </collision>
    </link>
    <joint name="panda_joint6" type="revolute">
        <safety_controller k_position="100.0" k_velocity="40.0" soft_lower_limit="-0.0175" soft_upper_limit="3.7525" />
        <origin rpy="1.57079632679 0 0" xyz="0 0 0" />
        <parent link="panda_link5" />
        <child link="panda_link6" />
        <axis xyz="0 0 1" />
        <limit effort="12" lower="-0.0873" upper="3.8223" velocity="2.6100" />
    </joint>
    <link name="panda_link7">
        <inertial>
            <origin xyz="0 0 0" rpy="0 0 0" />
            <mass value="3.06" />
            <inertia ixx="0.3" ixy="0.0" ixz="0.0" iyy="0.3" iyz="0.0" izz="0.3" />
        </inertial>
        <visual>
            <geometry>
                <mesh filename="package://franka_description/meshes/visual/link7.dae" />
            </geometry>
            <material name="panda_white" />
        </visual>
        <collision>
            <geometry>
                <mesh filename="package://franka_description/meshes/collision/link7.stl" />
            </geometry>
            <material name="panda_white" />
        </collision>
    </link>
    <joint name="panda_joint7" type="revolute">
        <safety_controller k_position="100.0" k_velocity="40.0" soft_lower_limit="-2.8973" soft_upper_limit="2.8973" />
        <origin rpy="1.57079632679 0 0" xyz="0.088 0 0" />
        <parent link="panda_link6" />
        <child link="panda_link7" />
        <axis xyz="0 0 1" />
        <limit effort="12" lower="-2.9671" upper="2.9671" velocity="2.6100" />
    </joint>
    <link name="panda_link8">
        <inertial>
            <origin xyz="0 0 0" rpy="0 0 0" />
            <mass value="3.06" />
            <inertia ixx="0.3" ixy="0.0" ixz="0.0" iyy="0.3" iyz="0.0" izz="0.3" />
        </inertial>
    </link>
    <joint name="panda_joint8" type="fixed">
        <origin rpy="0 0 0" xyz="0 0 0.107" />
        <parent link="panda_link7" />
        <child link="panda_link8" />
        <axis xyz="0 0 0" />
    </joint>
    <joint name="panda_hand_joint" type="fixed">
        <parent link="panda_link8" />
        <child link="panda_hand" />
        <origin rpy="0 0 -0.785398163397" xyz="0 0 0" />
    </joint>
    <link name="panda_hand">
        <!-- <visual>
      <geometry>
        <mesh filename="package://franka_description/meshes/visual/hand.dae"/>
      </geometry>
      <material name="panda_white"/>
    </visual>
    <collision>
      <geometry>
        <mesh filename="package://franka_description/meshes/collision/hand.stl"/>
      </geometry>
      <material name="panda_white"/>
    </collision> -->
        <inertial>
            <origin xyz="0 0 0" rpy="0 0 0" />
            <mass value="0.68" />
            <inertia ixx="0.1" ixy="0.0" ixz="0.0" iyy="0.1" iyz="0.0" izz="0.1" />
        </inertial>
        <visual>
            <origin xyz="0. 0. 0." rpy="0. 0. 0." />
            <geometry>
                <mesh filename="package://panda_w_realsense_description/meshes/panda_hand_ID234_001.obj" scale="1. 1. 1." />
            </geometry>
            <material name="panda_white" />
        </visual>
        <visual>
            <origin xyz="0. 0. 0." rpy="0. 0. 0." />
            <geometry>
                <mesh filename="package://panda_w_realsense_description/meshes/panda_hand_ID234_001frA.obj" scale="1. 1. 1." />
            </geometry>
            <material name="panda_white" />
        </visual>
        <visual>
            <origin xyz="0. 0. 0." rpy="0. 0. 0." />
            <geometry>
                <mesh filename="package://panda_w_realsense_description/meshes/panda_hand_ID234_001jEI.obj" scale="1. 1. 1." />
            </geometry>
            <material name="panda_white" />
        </visual>
        <visual>
            <origin xyz="0. 0. 0." rpy="0. 0. 0." />
            <geometry>
                <mesh filename="package://panda_w_realsense_description/meshes/panda_hand_ID234_001m4u.obj" scale="1. 1. 1." />
            </geometry>
            <material name="panda_white" />
        </visual>
        <visual>
            <origin xyz="0. 0. 0." rpy="0. 0. 0.0000002" />
            <geometry>
                <mesh filename="package://panda_w_realsense_description/meshes/realsense_ID4_000.obj" scale="1. 1. 1." />
            </geometry>
            <material name="panda_white" />
        </visual>
        <visual>
            <origin xyz="0. 0. 0." rpy="0. 0. 0.0000002" />
            <geometry>
                <mesh filename="package://panda_w_realsense_description/meshes/realsense_ID4_000frA.obj" scale="1. 1. 1." />
            </geometry>
            <material name="panda_white" />
        </visual>
        <visual>
            <origin xyz="0. 0. 0." rpy="0. 0. 0.0000002" />
            <geometry>
                <mesh filename="package://panda_w_realsense_description/meshes/realsense_ID4_000jEI.obj" scale="1. 1. 1." />
            </geometry>
            <material name="panda_white" />
        </visual>
        <visual>
            <origin xyz="0. 0. 0." rpy="0. 0. 0.0000002" />
            <geometry>
                <mesh filename="package://panda_w_realsense_description/meshes/realsense_ID4_000m4u.obj" scale="1. 1. 1." />
            </geometry>
            <material name="panda_white" />
        </visual>
        <collision>
            <origin xyz="0. 0. 0." rpy="0. 0. 0." />
            <geometry>
                <mesh filename="package://panda_w_realsense_description/meshes/panda_hand_ID234_001frA.obj" scale="1. 1. 1." />
            </geometry>
            <material name="panda_white" />
        </collision>
        <collision>
            <origin xyz="0. 0. 0." rpy="0. 0. 0." />
            <geometry>
                <mesh filename="package://panda_w_realsense_description/meshes/panda_hand_ID234_001m4u.obj" scale="1. 1. 1." />
            </geometry>
            <material name="panda_white" />
        </collision>
        <collision>
            <origin xyz="0. 0. 0." rpy="0. 0. 0.0000002" />
            <geometry>
                <mesh filename="package://panda_w_realsense_description/meshes/realsense_ID4_000.obj" scale="1. 1. 1." />
            </geometry>
            <material name="panda_white" />
        </collision>
        <collision>
            <origin xyz="0. 0. 0." rpy="0. 0. 0.0000002" />
            <geometry>
                <mesh filename="package://panda_w_realsense_description/meshes/realsense_ID4_000m4u.obj" scale="1. 1. 1." />
            </geometry>
            <material name="panda_white" />
        </collision>
    </link>
    <link name="panda_leftfinger">
        <!-- <visual>
      <geometry>
        <mesh filename="package://franka_description/meshes/visual/finger.dae"/>
      </geometry>
      <material name="panda_white"/>
    </visual>
    <collision>
      <geometry>
        <mesh filename="package://franka_description/meshes/collision/finger.stl"/>
      </geometry>
      <material name="panda_white"/>
    </collision> -->
        <inertial>
            <origin xyz="0 0 0" rpy="0 0 0" />
            <mass value="0.01" />
            <inertia ixx="0.1" ixy="0.0" ixz="0.0" iyy="0.1" iyz="0.0" izz="0.1" />
        </inertial>
        <visual>
            <origin xyz="0. 0. 0." rpy="0. 0. 0." />
            <geometry>
                <mesh filename="package://panda_w_realsense_description/meshes/geometry_ID27.obj" scale="1. 1. 1." />
            </geometry>
            <material name="panda_white" />
        </visual>
        <visual>
            <origin xyz="0. 0. 0." rpy="0. 0. 0." />
            <geometry>
                <mesh filename="package://panda_w_realsense_description/meshes/geometry_ID27fa3.obj" scale="1. 1. 1." />
            </geometry>
            <material name="panda_white" />
        </visual>
        <visual>
            <origin xyz="0. 0. 0." rpy="0. 0. 0." />
            <geometry>
                <mesh filename="package://panda_w_realsense_description/meshes/geometry_ID27SVM.obj" scale="1. 1. 1." />
            </geometry>
        </visual>
        <collision>
            <origin xyz="0. 0. 0." rpy="0. 0. 0." />
            <geometry>
                <mesh filename="package://panda_w_realsense_description/meshes/geometry_ID27.obj" scale="1. 1. 1." />
            </geometry>
            <material name="panda_white" />
        </collision>
        <collision>
            <origin xyz="0. 0. 0." rpy="0. 0. 0." />
            <geometry>
                <mesh filename="package://panda_w_realsense_description/meshes/geometry_ID27SVM.obj" scale="1. 1. 1." />
            </geometry>
            <material name="panda_white" />
        </collision>
    </link>
    <link name="panda_rightfinger">
        <!-- <visual>
      <origin rpy="0 0 3.14159265359" xyz="0 0 0"/>
      <geometry>
        <mesh filename="package://franka_description/meshes/visual/finger.dae"/>
      </geometry>
      <material name="panda_white"/>
    </visual>
    <collision>
      <origin rpy="0 0 3.14159265359" xyz="0 0 0"/>
      <geometry>
        <mesh filename="package://franka_description/meshes/collision/finger.stl"/>
      </geometry>
      <material name="panda_white"/>
    </collision> -->
        <inertial>
            <origin xyz="0 0 0" rpy="0 0 0" />
            <mass value="0.01" />
            <inertia ixx="0.1" ixy="0.0" ixz="0.0" iyy="0.1" iyz="0.0" izz="0.1" />
        </inertial>
        <visual>
            <origin xyz="0. 0. 0." rpy="0. 0. 3.1415927" />
            <geometry>
                <mesh filename="package://panda_w_realsense_description/meshes/geometry_ID27.obj" scale="1. 1. 1." />
            </geometry>
            <material name="panda_white" />
        </visual>
        <visual>
            <origin xyz="0. 0. 0." rpy="0. 0. 3.1415927" />
            <geometry>
                <mesh filename="package://panda_w_realsense_description/meshes/geometry_ID27fa3.obj" scale="1. 1. 1." />
            </geometry>
            <material name="panda_white" />
        </visual>
        <visual>
            <origin xyz="0. 0. 0." rpy="0. 0. 3.1415927" />
            <geometry>
                <mesh filename="package://panda_w_realsense_description/meshes/geometry_ID27SVM.obj" scale="1. 1. 1." />
            </geometry>
            <material name="panda_white" />
        </visual>
        <collision>
            <origin xyz="0. 0. 0." rpy="0. 0. 3.1415927" />
            <geometry>
                <mesh filename="package://panda_w_realsense_description/meshes/geometry_ID27.obj" scale="1. 1. 1." />
            </geometry>
            <material name="panda_white" />
        </collision>
        <collision>
            <origin xyz="0. 0. 0." rpy="0. 0. 3.1415927" />
            <geometry>
                <mesh filename="package://panda_w_realsense_description/meshes/geometry_ID27SVM.obj" scale="1. 1. 1." />
            </geometry>
            <material name="panda_white" />
        </collision>
    </link>
    <joint name="panda_finger_joint1" type="prismatic">
        <parent link="panda_hand" />
        <child link="panda_leftfinger" />
        <origin rpy="0 0 0" xyz="0 0 0.0584" />
        <axis xyz="0 1 0" />
        <limit effort="20" lower="0.0" upper="0.04" velocity="0.2" />
    </joint>
    <joint name="panda_finger_joint2" type="prismatic">
        <parent link="panda_hand" />
        <child link="panda_rightfinger" />
        <origin rpy="0 0 0" xyz="0 0 0.0584" />
        <axis xyz="0 -1 0" />
        <limit effort="20" lower="0.0" upper="0.04" velocity="0.2" />
        <mimic joint="panda_finger_joint1" />
    </joint>
    <material name="panda_white">
        <color rgba="1. 1. 1. 1." />
    </material>

    <transmission name="trans_panda_joint1">
        <type>transmission_interface/SimpleTransmission</type>
        <joint name="panda_joint1">
            <hardwareInterface>hardware_interface/EffortJointInterface</hardwareInterface>
        </joint>
        <actuator name="panda_joint1_motor">
            <hardwareInterface>hardware_interface/EffortJointInterface</hardwareInterface>
            <mechanicalReduction>1</mechanicalReduction>
        </actuator>
    </transmission>
    <transmission name="trans_panda_joint2">
        <type>transmission_interface/SimpleTransmission</type>
        <joint name="panda_joint2">
            <hardwareInterface>hardware_interface/EffortJointInterface</hardwareInterface>
        </joint>
        <actuator name="panda_joint2_motor">
            <hardwareInterface>hardware_interface/EffortJointInterface</hardwareInterface>
            <mechanicalReduction>1</mechanicalReduction>
        </actuator>
    </transmission>
    <transmission name="trans_panda_joint3">
        <type>transmission_interface/SimpleTransmission</type>
        <joint name="panda_joint3">
            <hardwareInterface>hardware_interface/EffortJointInterface</hardwareInterface>
        </joint>
        <actuator name="panda_joint3_motor">
            <hardwareInterface>hardware_interface/EffortJointInterface</hardwareInterface>
            <mechanicalReduction>1</mechanicalReduction>
        </actuator>
    </transmission>
    <transmission name="trans_panda_joint4">
        <type>transmission_interface/SimpleTransmission</type>
        <joint name="panda_joint4">
            <hardwareInterface>hardware_interface/EffortJointInterface</hardwareInterface>
        </joint>
        <actuator name="panda_joint4_motor">
            <hardwareInterface>hardware_interface/EffortJointInterface</hardwareInterface>
            <mechanicalReduction>1</mechanicalReduction>
        </actuator>
    </transmission>
    <transmission name="trans_panda_joint5">
        <type>transmission_interface/SimpleTransmission</type>
        <joint name="panda_joint5">
            <hardwareInterface>hardware_interface/EffortJointInterface</hardwareInterface>
        </joint>
        <actuator name="panda_joint5_motor">
            <hardwareInterface>hardware_interface/EffortJointInterface</hardwareInterface>
            <mechanicalReduction>1</mechanicalReduction>
        </actuator>
    </transmission>
    <transmission name="trans_panda_joint6">
        <type>transmission_interface/SimpleTransmission</type>
        <joint name="panda_joint6">
            <hardwareInterface>hardware_interface/EffortJointInterface</hardwareInterface>
        </joint>
        <actuator name="panda_joint6_motor">
            <hardwareInterface>hardware_interface/EffortJointInterface</hardwareInterface>
            <mechanicalReduction>1</mechanicalReduction>
        </actuator>
    </transmission>
    <transmission name="trans_panda_joint7">
        <type>transmission_interface/SimpleTransmission</type>
        <joint name="panda_joint7">
            <hardwareInterface>hardware_interface/EffortJointInterface</hardwareInterface>
        </joint>
        <actuator name="panda_joint7_motor">
            <hardwareInterface>hardware_interface/EffortJointInterface</hardwareInterface>
            <mechanicalReduction>1</mechanicalReduction>
        </actuator>
    </transmission>
    <transmission name="trans_panda_finger_joint1">
        <type>transmission_interface/SimpleTransmission</type>
        <joint name="panda_finger_joint1">
            <hardwareInterface>hardware_interface/EffortJointInterface</hardwareInterface>
        </joint>
        <actuator name="panda_finger_joint1_motor">
            <hardwareInterface>hardware_interface/EffortJointInterface</hardwareInterface>
            <mechanicalReduction>1</mechanicalReduction>
        </actuator>
    </transmission>
    <transmission name="trans_panda_finger_joint2">
        <type>transmission_interface/SimpleTransmission</type>
        <joint name="panda_finger_joint2">
            <hardwareInterface>hardware_interface/EffortJointInterface</hardwareInterface>
        </joint>
        <actuator name="panda_finger_joint2_motor">
            <hardwareInterface>hardware_interface/EffortJointInterface</hardwareInterface>
            <mechanicalReduction>1</mechanicalReduction>
        </actuator>
    </transmission>
    <gazebo>
        <plugin name="gazebo_ros_control">
            <robotNamespace>/</robotNamespace>
        </plugin>
    </gazebo>
</robot>

